Workbook

Sheet Utilisateurs
B2: FLEAP | C2: Wienerberger - Utilisateurs
B4: Utilisateurs | G4: Autorisation
B5: Civilité | C5: Nom | D5: Prénom | E5: Email | G5: Site N°1 | H5: Site N°2
B6: Madame | C6: Baumert | D6: Laura | E6: laura.baumert@wienerberger.com | G6: Oui | H6: Oui

Sheet dénomination_ced
A1: =CLEAN(B1) -> 01 01 | B1: 01 01 | C1: Déchets provenant de l'extraction des minéraux :
A2: =CLEAN(B2) -> 01 01 01 | B2: 01 01 01 | C2: déchets provenant de l'extraction des minéraux métallifères ;
A3: =CLEAN(B3) -> 01 01 02 | B3: 01 01 02 | C3: déchets provenant de l'extraction des minéraux non métallifères.
A4: =CLEAN(B4)
A5: =CLEAN(B5) -> 01 03 | B5: 01 03 | C5: Déchets provenant de la transformation physique et chimique des minéraux métallifères
A6: =CLEAN(B6) -> 01 03 04* | B6: 01 03 04* | C6: stériles acidogènes provenant de la transformation du sulfure
A7: =CLEAN(B7) -> 01 03 05* | B7: 01 03 05* | C7: autres stériles contenant des substances dangereuses
A8: =CLEAN(B8) -> 01 03 06 | B8: 01 03 06 | C8: stériles autres que ceux visés aux rubriques 01 03 04 et 01 03 05
A9: =CLEAN(B9) -> 01 03 07* | B9: 01 03 07* | C9: autres déchets contenant des substances dangereuses provenant de la transformation physique et chimique des minéraux métallifères
A10: =CLEAN(B10) -> 01 03 08 | B10: 01 03 08 | C10: déchets de poussières et de poudres autres que ceux visés à la rubrique 01 03 07
A11: =CLEAN(B11) -> 01 03 09 | B11: 01 03 09 | C11: boues rouges issues de la production d'alumine autres que celles visées à la rubrique 01 03 10
A12: =CLEAN(B12) -> 01 03 10* | B12: 01 03 10* | C12: boues rouges issues de la production d'alumine contenant des substances dangereuses, autres que les déchets visés à la rubrique 01 03 07
A13: =CLEAN(B13) -> 01 03 99 | B13: 01 03 99 | C13: déchets non spécifiés ailleurs
A14: =CLEAN(B14)
A15: =CLEAN(B15) -> 01 04 | B15: 01 04 | C15: Déchets provenant de la transformation physique et chimique des minéraux non métallifères :
A16: =CLEAN(B16) -> 01 04 07* | B16: 01 04 07* | C16: déchets contenant des substances dangereuses provenant de la transformation physique et chimique des minéraux non métallifères ;
A17: =CLEAN(B17) -> 01 04 08 | B17: 01 04 08 | C17: déchets de graviers et débris de pierres autres que ceux visés à la rubrique 01 04 07 ;
A18: =CLEAN(B18) -> 01 04 09 | B18: 01 04 09 | C18: déchets de sable et d'argile ;
A19: =CLEAN(B19) -> 01 04 10 | B19: 01 04 10 | C19: déchets de poussières et de poudres autres que ceux visés à la rubrique 01 04 07 ;
A20: =CLEAN(B20) -> 01 04 11 | B20: 01 04 11 | C20: déchets de la transformation de la potasse et des sels minéraux autres que ceux visés à la rubrique 01 04 07 ;
A21: =CLEAN(B21) -> 01 04 12 | B21: 01 04 12 | C21: stériles et autres déchets, provenant du lavage et du nettoyage des minéraux, autres que ceux visés aux rubriques 01 04 07 et 01 04 11 ;
A22: =CLEAN(B22) -> 01 04 13 | B22: 01 04 13 | C22: déchets provenant de la taille et du sciage des pierres autres que ceux visés à la rubrique 01 04 07 ;
A23: =CLEAN(B23) -> 01 04 99 | B23: 01 04 99 | C23: déchets non spécifiés ailleurs.
A24: =CLEAN(B24)
A25: =CLEAN(B25) -> 01 05 | B25: 01 05 | C25: Boues de forage et autres déchets de forage :
A26: =CLEAN(B26) -> 01 05 04 | B26: 01 05 04 | C26: boues et autres déchets de forage à l'eau douce
A27: =CLEAN(B27) -> 01 05 05* | B27: 01 05 05* | C27: boues et autres déchets de forage contenant des hydrocarbures
A28: =CLEAN(B28) -> 01 05 06* | B28: 01 05 06* | C28: boues de forage et autres déchets de forage contenant des substances dangereuses
A29: =CLEAN(B29) -> 01 05 07 | B29: 01 05 07 | C29: boues et autres déchets de forage contenant des sels de baryum, autres que ceux visés aux rubriques 01 05 05 et 01 05 06
A30: =CLEAN(B30) -> 01 05 08 | B30: 01 05 08 | C30: boues et autres déchets de forage contenant des chlorures, autres que ceux visés aux rubriques 01 05 05 et 01 05 06
A31: =CLEAN(B31) -> 01 05 99 | B31: 01 05 99 | C31: déchets non spécifiés ailleurs
A32: =CLEAN(B32)
A33: =CLEAN(B33) -> 02 Déchets provenant de l'agriculture, de l'horticulture, de l'aquaculture, de la sylviculture, de la chasse et de la pêche ainsi que de la préparation et de la transformation des aliments ; | B33: 02 Déchets provenant de l'agriculture, de l'horticulture, de l'aquaculture, de la sylviculture, de la chasse et de la pêche ainsi que de la préparation et de la transformation des aliments ;
A34: =CLEAN(B34)
A35: =CLEAN(B35) -> 02 01 | B35: 02 01 | C35: Déchets provenant de l'agriculture, de l'horticulture, de l'aquaculture, de la sylviculture, de la chasse et de la pêche :
A36: =CLEAN(B36) -> 02 01 01 | B36: 02 01 01 | C36: boues provenant du lavage et du nettoyage
A37: =CLEAN(B37) -> 02 01 02 | B37: 02 01 02 | C37: déchets de tissus animaux
A38: =CLEAN(B38) -> 02 01 03 | B38: 02 01 03 | C38: déchets de tissus végétaux
A39: =CLEAN(B39) -> 02 01 04 | B39: 02 01 04 | C39: déchets de matières plastiques (à l'exclusion des emballages)
A40: =CLEAN(B40) -> 02 01 06 | B40: 02 01 06 | C40: fèces, urine et fumier (y compris paille souillée), effluents, collectés séparément et traités hors site
...

Sheet template_code
A1: site_nom | B1: site_siret | C1: site_adresse | D1: site_gerep | E1: filiere_nom | F1: ced | G1: description_ced | H1: denomination_ced | I1: consistance | J1: cap | L1: adr | M1: onu | N1: onu_denomination | O1: classe_de_danger | P1: groupe_emballage | R1: adresse_collecte | T1: producteur_nom | U1: producteur_personne_lastname | V1: producteur_personne_firstname | W1: producteur_personne_tel | X1: producteur_personne_email | Z1: operationelle_personne_lastname | AA1: operationelle_personne_firstname | AB1: operationelle_personne_tel | AC1: operationelle_personne_email | AE1: contenant_nom | AF1: contenant_code | AG1: contenant_identifiant | AH1: contenant_description | AI1: contenant_volume_unitaire | AJ1: contenant_nombre_indicatif | AK1: contenant_proprio_ou_location | AL1: contenant_prestataire_nom | AM1: contenant_prestataire_siret | AO1: eco_organisme_nom | AP1: eco_organisme_siret | AR1: negociant_nom | AS1: negociant_siret | AT1: negociant_adresse | AU1: negociant_recipisse_numero | AW1: negociant_personne_lastname | AX1: negociant_personne_firstname | AY1: negociant_personne_tel | AZ1: negociant_personne_email | BB1: negociant_personne_collecte_lastname | BC1: negociant_personne_collecte_firstname | BD1: negociant_personne_collecte_tel | BE1: negociant_personne_collecte_email | BG1: transporteur_nom | BH1: transporteur_siret | BI1: transporteur_adresse | BJ1: transporteur_recipisse_numero | BL1: transporteur_personne_lastname | BM1: transporteur_personne_firstname | BN1: transporteur_personne_tel | BO1: transporteur_personne_email | BQ1: transporteur_personne_collecte_lastname | BR1: transporteur_personne_collecte_firstname | BS1: transporteur_personne_collecte_tel | BT1: transporteur_personne_collecte_email | BV1: installation_intermediaire_nom | BW1: installation_intermediaire_siret | BX1: installation_intermediaire_adresse | BY1: installation_intermediaire_recipisse_numero | BZ1: installation_intermediaire_code_traitement | CB1: installation_intermediaire_personne_lastname | CC1: installation_intermediaire_personne_firstname | CD1: installation_intermediaire_personne_tel | CE1: installation_intermediaire_personne_email | CG1: prestataire_final_nom | CH1: prestataire_final_siret | CI1: prestataire_final_adresse | CJ1: prestataire_final_recipisse_numero | CK1: prestataire_final_code_traitement | CL1: prestataire_final_traitement_qualification | CN1: prestataire_final_personne_lastname | CO1: prestataire_final_personne_firstname | CP1: prestataire_final_personne_tel | CQ1: prestataire_final_personne_email
A2: Usine Achenheim | B2: 54850098200044 | C2: 5 rue du Canal 67204 Achenheim | E2: Aérosols et Gaz | F2: 16 05 04* | H2: {=IFERROR(INDEX(dénomination_ced!$C$2:$C$1102, MATCH(F2, dénomination_ced!$C$1:$C$1102, 0)), "Non classifié")} -> Non classifié | I2: LIQUID | J2: WEE2838942 | L2: UN 1789, acide chlorhydrique, 8, II, (E) | M2: 1789 | N2: acide chlorhydrique | O2: 7 | P2: II | T2: Wienerberger | U2: Baumert | V2: Laura | W2: 06 12 33 76 40 | X2: laura.baumert@wienerberger.com | Z2: Bauvier | AA2: Carinne | AB2: 06 44 44 44 44 | AC2: carinne.bauvier@wienerberger.com | AE2: GRV | AF2: GRV | AH2: Grand Récipient Pour Vrac | AI2: 1000L | AJ2: 5 | AK2: Propriétaire | AO2: non concerné | AP2: non concerné | BG2: Chimirec Est | BH2: 39933934000016 | BI2: ZI La Haie Sorette 54450 Domjevin | BJ2: TR547592024 | BL2: Camion | BM2: Luc | BN2: 05 44 44 44 44 | BO2: l.c@transpo.fr | BQ2: lechateau | BR2: Laurent | BS2: 09 09 09 09 09 | BT2: lefifi@lemail.fr | BV2: Chimirec Est | BW2: ############# | BX2: ZI La Haie Sorette 54450 Domjevin | BZ2: R12 | CB2: Legrand | CC2: Marcel | CD2: 33 33 33 33 33 | CE2: legrand@marcel.fr | CG2: Autorisation par arrêté préfectoral, à une rupture de traçabilité pour ce déchet | CK2: R4 | CL2: Recyclage | CN2: Lepoint | CO2: Martin | CP2: 87 56 76 87 98 | CQ2: lepoint@outlook.fr
A3: Usine Achenheim | B3: 54850098200044 | C3: 5 rue du Canal 67204 Achenheim | E3: Déchets de Bois et Papier | F3: 15 01 03 | H3: {=IFERROR(INDEX(dénomination_ced!$C$2:$C$1102, MATCH(F3, dénomination_ced!$C$1:$C$1102, 0)), "Non classifié")} -> Non classifié | I3: SOLID | J3: WEE2838943 | L3: non concerné | M3: non concerné | N3: non concerné | O3: non concerné | P3: non concerné | T3: Wienerberger | U3: Baumert | V3: Laura | W3: 06 12 33 76 40 | X3: laura.baumert@wienerberger.com | Z3: Bauvier | AA3: Carinne | AB3: 06 44 44 44 44 | AC3: carinne.bauvier@wienerberger.com | AE3: GRV | AF3: GRV | AH3: Grand Récipient Pour Vrac | AI3: 1000L | AJ3: 5 | AK3: Propriétaire | AO3: non concerné | AP3: non concerné | BG3: Suez | BH3: 50 472 678 700 030 | BI3: 13 route de Rohrshollen 67100 Strasbourg | BJ3: 2167061 | BL3: Camion | BM3: Luc | BN3: 05 44 44 44 44 | BO3: l.c@transpo.fr | BQ3: lechateau | BR3: Laurent | BS3: 09 09 09 09 09 | BT3: lefifi@lemail.fr | CG3: SARDI | CH3: 35238105700038 | CI3: 15 route du Rohrschollen 67000 Strasbourg | CK3: R5 | CL3: Recyclage | CN3: Lepoint | CO3: Martin | CP3: 87 56 76 87 98 | CQ3: lepoint@outlook.fr
A4: Usine Achenheim | B4: 54850098200044 | C4: 5 rue du Canal 67204 Achenheim | E4: Non classifié | F4: 13 05 02* | G4: Boues de séparateurs - eaux/hydrocarbures | H4: {=IFERROR(INDEX(dénomination_ced!$C$2:$C$1102, MATCH(F4, dénomination_ced!$C$1:$C$1102, 0)), "Non classifié")} -> Non classifié | I4: LIQUID | J4: WEE2838944 | L4: UN 1742, acide chlorhydrique, 8, II, (E) | M4: 1742 | N4: acide chlorhydrique | O4: 7 | P4: II | T4: Wienerberger | U4: Baumert | V4: Laura | W4: 06 12 33 76 40 | X4: laura.baumert@wienerberger.com | Z4: Bauvier | AA4: Carinne | AB4: 06 44 44 44 44 | AC4: carinne.bauvier@wienerberger.com | AE4: GRV | AF4: GRV | AH4: Grand Récipient Pour Vrac | AI4: 1000L | AJ4: 5 | AK4: Propriétaire | AO4: non concerné | AP4: non concerné | BG4: Suez | BH4: 50 472 678 700 030 | BI4: 13 route de Rohrshollen 67100 Strasbourg | BJ4: 2167061 | BL4: Camion | BM4: Luc | BN4: 05 44 44 44 44 | BO4: l.c@transpo.fr | BQ4: lechateau | BR4: Laurent | BS4: 09 09 09 09 09 | BT4: lefifi@lemail.fr | CG4: SARDI | CH4: 35 238 105 700 038 | CI4: 15 route du Rohrschollen 67000 Strasbourg | CK4: R5 | CL4: Recyclage | CN4: Lepoint | CO4: Martin | CP4: 87 56 76 87 98 | CQ4: lepoint@outlook.fr
A5: Usine Achenheim | B5: 54850098200044 | C5: 5 rue du Canal 67204 Achenheim | E5: Déchets Plastiques | F5: 15 01 06 | G5: Bouteilles plastiques et canettes | H5: {=IFERROR(INDEX(dénomination_ced!$C$2:$C$1102, MATCH(F5, dénomination_ced!$C$1:$C$1102, 0)), "Non classifié")} -> Non classifié | I5: SOLID | J5: WEE2838945 | L5: non concerné | M5: non concerné | N5: non concerné | O5: non concerné | P5: non concerné | T5: Wienerberger | U5: Baumert | V5: Laura | W5: 06 12 33 76 40 | X5: laura.baumert@wienerberger.com | Z5: Bauvier | AA5: Carinne | AB5: 06 44 44 44 44 | AC5: carinne.bauvier@wienerberger.com | AE5: GRV | AF5: GRV | AH5: Grand Récipient Pour Vrac | AI5: 1000L | AJ5: 7 | AK5: Propriétaire | AO5: non concerné | AP5: non concerné | BG5: Schroll | BH5: 32 519 337 300 017 | BI5: 6 rue de Cherbourg 67100 Strasbourg | BJ5: 2067081 | BL5: Camion | BM5: Luc | BN5: 05 44 44 44 44 | BO5: l.c@transpo.fr | BQ5: lechateau | BR5: Laurent | BS5: 09 09 09 09 09 | BT5: lefifi@lemail.fr | CG5: Schroll | CH5: 32 519 337 300 017 | CI5: 6 rue de Cherbourg 67100 Strasbourg | CK5: R5 | CL5: Recyclage | CN5: Lepoint | CO5: Martin | CP5: 87 56 76 87 98 | CQ5: lepoint@outlook.fr
A6: Usine Achenheim | B6: 54850098200044 | C6: 5 rue du Canal 67204 Achenheim | E6: Déchets Technologiques et Électroniques | F6: 15 01 10* | G6: (salle archives garage) | H6: {=IFERROR(INDEX(dénomination_ced!$C$2:$C$1102, MATCH(F6, dénomination_ced!$C$1:$C$1102, 0)), "Non classifié")} -> Non classifié | I6: SOLID | J6: WEE2838946 | L6: UN 1777, acide chlorhydrique, 8, II, (E) | M6: 1777 | N6: acide chlorhydrique | O6: 7 | P6: II | T6: Wienerberger | U6: Baumert | V6: Laura | W6: 06 12 33 76 40 | X6: laura.baumert@wienerberger.com | Z6: Bauvier | AA6: Carinne | AB6: 06 44 44 44 44 | AC6: carinne.bauvier@wienerberger.com | AE6: GRV | AF6: GRV | AH6: Grand Récipient Pour Vrac | AI6: 1000L | AJ6: 7 | AK6: Propriétaire | AO6: non concerné | AP6: non concerné | BG6: EDIB | BH6: 30223694800030 | BI6: QUAI DU CANAL 67270 HOCHFELDEN | BJ6: 7540873 | BL6: Camion | BM6: Luc | BN6: 05 44 44 44 44 | BO6: l.c@transpo.fr | BQ6: lechateau | BR6: Laurent | BS6: 09 09 09 09 09 | BT6: lefifi@lemail.fr | BV6: EDIB | BW6: ############# | BX6: QUAI DU CANAL 67270 HOCHFELDEN | BZ6: R13 | CB6: Legrand | CC6: Marcel | CD6: 33 33 33 33 33 | CE6: legrand@marcel.fr | CG6: EDIB | CH6: 30223694800030 | CI6: QUAI DU CANAL 67270 HOCHFELDEN | CK6: R1 | CL6: Valorisation | CN6: Lepoint | CO6: Martin | CP6: 87 56 76 87 98 | CQ6: lepoint@outlook.fr
A7: Usine Achenheim | B7: 54850098200044 | C7: 5 rue du Canal 67204 Achenheim | E7: Aérosols et Gaz | F7: 10 01 18* | G7: (poudres non chlorées) | H7: {=IFERROR(INDEX(dénomination_ced!$C$2:$C$1102, MATCH(F7, dénomination_ced!$C$1:$C$1102, 0)), "Non classifié")} -> Non classifié | I7: SOLID | J7: WEE2838947 | L7: UN 1774, acide chlorhydrique, 8, II, (E) | M7: 1774 | N7: acide chlorhydrique | O7: 7 | P7: II | T7: Wienerberger | U7: Baumert | V7: Laura | W7: 06 12 33 76 40 | X7: laura.baumert@wienerberger.com | Z7: Bauvier | AA7: Carinne | AB7: 06 44 44 44 44 | AC7: carinne.bauvier@wienerberger.com | AE7: GRV | AF7: GRV | AH7: Grand Récipient Pour Vrac | AI7: 1000L | AJ7: 7 | AK7: Propriétaire | AO7: non concerné | AP7: non concerné | BG7: Chimirec Est | BH7: 39933934000016 | BI7: ZI La Haie Sorette 54450 Domjevin | BJ7: TR547592024 | BL7: Camion | BM7: Luc | BN7: 05 44 44 44 44 | BO7: l.c@transpo.fr | BQ7: lechateau | BR7: Laurent | BS7: 09 09 09 09 09 | BT7: lefifi@lemail.fr | BV7: Chimirec Est | BW7: ############# | BX7: ZI La Haie Sorette 54450 Domjevin | BZ7: R12 | CB7: Legrand | CC7: Marcel | CD7: 33 33 33 33 33 | CE7: legrand@marcel.fr | CG7: Autorisation par arrêté préfectoral, à une rupture de traçabilité pour ce déchet | CK7: R12 | CL7: Recyclage | CN7: Lepoint | CO7: Martin | CP7: 87 56 76 87 98 | CQ7: lepoint@outlook.fr
A8: Usine Achenheim | B8: 54850098200044 | C8: 5 rue du Canal 67204 Achenheim | E8: Déchets Bâtiment et Construction | F8: 17 05 04 | H8: {=IFERROR(INDEX(dénomination_ced!$C$2:$C$1102, MATCH(F8, dénomination_ced!$C$1:$C$1102, 0)), "Non classifié")} -> Non classifié | I8: SOLID | J8: WEE2838948 | L8: non concerné | M8: non concerné | N8: non concerné | O8: non concerné | P8: non concerné | T8: Wienerberger | U8: Baumert | V8: Laura | W8: 06 12 33 76 40 | X8: laura.baumert@wienerberger.com | Z8: Bauvier | AA8: Carinne | AB8: 06 44 44 44 44 | AC8: carinne.bauvier@wienerberger.com | AE8: GRV | AF8: GRV | AH8: Grand Récipient Pour Vrac | AI8: 1000L | AJ8: 12 | AK8: Propriétaire | AO8: non concerné | AP8: non concerné | BG8: Lingenheld | BH8: 38 535 103 600 053 | BI8: Carrefour Bellevue, Chemin du Hitzthal 67203 Oberschaeffolsheim | BJ8: non soumis | BL8: Camion | BM8: Luc | BN8: 05 44 44 44 44 | BO8: l.c@transpo.fr | BQ8: lechateau | BR8: Laurent | BS8: 09 09 09 09 09 | BT8: lefifi@lemail.fr | CB8: Legrand | CC8: Marcel | CD8: 33 33 33 33 33 | CE8: legrand@marcel.fr | CG8: Lingenheld | CH8: 38 535 103 600 053 | CI8: Carrefour Bellevue, Chemin du Hitzthal 67203 Oberschaeffolsheim | CK8: R5/D1 | CL8: Valorisation (briques) + élimination (terre+DIB) | CN8: Lepoint | CO8: Martin | CP8: 87 56 76 87 98 | CQ8: lepoint@outlook.fr
A9: Usine Achenheim | B9: 54850098200044 | C9: 5 rue du Canal 67204 Achenheim | E9: Non classifié | F9: 16 07 08* | G9: provenant de la fosse élévateur manutention produit vert (intervention du 13/11/2023) | H9: {=IFERROR(INDEX(dénomination_ced!$C$2:$C$1102, MATCH(F9, dénomination_ced!$C$1:$C$1102, 0)), "Non classifié")} -> Non classifié | I9: SOLID | J9: WEE2838949 | L9: UN 1734, acide chlorhydrique, 8, II, (E) | M9: 1734 | N9: acide chlorhydrique | O9: 7 | P9: II | T9: Wienerberger | U9: Baumert | V9: Laura | W9: 06 12 33 76 40 | X9: laura.baumert@wienerberger.com | Z9: Bauvier | AA9: Carinne | AB9: 06 44 44 44 44 | AC9: carinne.bauvier@wienerberger.com | AE9: GRV | AF9: GRV | AH9: Grand Récipient Pour Vrac | AI9: 1000L | AJ9: 12 | AK9: Propriétaire | AO9: non concerné | AP9: non concerné | BG9: Transports Geissel | BH9: 39002820700020 | BI9: 18 rue de l'Energie 67870 Griesheim-Près-Molsheim | BJ9: 2267008 | BL9: Camion | BM9: Luc | BN9: 05 44 44 44 44 | BO9: l.c@transpo.fr | BQ9: lechateau | BR9: Laurent | BS9: 09 09 09 09 09 | BT9: lefifi@lemail.fr | CG9: Evapur | CH9: 45025886800022 | CI9: 1 boucle du Carreau de la Mine 57100 Thionville | CK9: R3 | CL9: Recyclage | CN9: Lepoint | CO9: Martin | CP9: 87 56 76 87 98 | CQ9: lepoint@outlook.fr
A10: Usine Achenheim | B10: 54850098200044 | C10: 5 rue du Canal 67204 Achenheim | E10: Non classifié | F10: 16 07 08* | G10: provenant des fosses élévateurs et de 4 bacs de rétention (intervention du 19/12/2023) | H10: {=IFERROR(INDEX(dénomination_ced!$C$2:$C$1102, MATCH(F10, dénomination_ced!$C$1:$C$1102, 0)), "Non classifié")} -> Non classifié | I10: SOLID | J10: WEE2838950 | L10: UN 1734, acide chlorhydrique, 8, II, (E) | M10: 1734 | N10: acide chlorhydrique | O10: 7 | P10: II | T10: Wienerberger | U10: Baumert | V10: Laura | W10: 06 12 33 76 40 | X10: laura.baumert@wienerberger.com | Z10: Bauvier | AA10: Carinne | AB10: 06 44 44 44 44 | AC10: carinne.bauvier@wienerberger.com | AE10: GRV | AF10: GRV | AH10: Grand Récipient Pour Vrac | AI10: 1000L | AJ10: 1 | AK10: Propriétaire | AO10: non concerné | AP10: non concerné | BG10: Transports Geissel | BH10: 39002820700020 | BI10: 18 rue de l'Energie 67870 Griesheim-Près-Molsheim | BJ10: 2267008 | BL10: Camion | BM10: Luc | BN10: 05 44 44 44 44 | BO10: l.c@transpo.fr | BQ10: lechateau | BR10: Laurent | BS10: 09 09 09 09 09 | BT10: lefifi@lemail.fr | CG10: Evapur | CH10: 45025886800022 | CI10: 1 boucle du Carreau de la Mine 57100 Thionville | CK10: R3 | CL10: Recyclage | CN10: Lepoint | CO10: Martin | CP10: 87 56 76 87 98 | CQ10: lepoint@outlook.fr
A11: Usine Achenheim | B11: 54850098200044 | C11: 5 rue du Canal 67204 Achenheim | E11: Déchets Technologiques et Électroniques | F11: 16 02 13* | H11: {=IFERROR(INDEX(dénomination_ced!$C$2:$C$1102, MATCH(F11, dénomination_ced!$C$1:$C$1102, 0)), "Non classifié")} -> Non classifié | I11: SOLID | J11: WEE2838951 | L11: non concerné | M11: non concerné | N11: non concerné | O11: non concerné | P11: non concerné | T11: Wienerberger | U11: Baumert | V11: Laura | W11: 06 12 33 76 40 | X11: laura.baumert@wienerberger.com | Z11: Bauvier | AA11: Carinne | AB11: 06 44 44 44 44 | AC11: carinne.bauvier@wienerberger.com | AE11: GRV | AF11: GRV | AH11: Grand Récipient Pour Vrac | AI11: 1000L | AJ11: 1 | AK11: Propriétaire | AO11: non concerné | AP11: non concerné | BG11: Chimirec Est | BH11: 39933934000016 | BI11: ZI La Haie Sorette 54450 Domjevin | BJ11: TR547592024 | BL11: Camion | BM11: Luc | BN11: 05 44 44 44 44 | BO11: l.c@transpo.fr | BQ11: lechateau | BR11: Laurent | BS11: 09 09 09 09 09 | BT11: lefifi@lemail.fr | BV11: Chimirec Est | BW11: ############# | BX11: ZI La Haie Sorette 54450 Domjevin | BZ11: R12 | CB11: Legrand | CC11: Marcel | CD11: 33 33 33 33 33 | CE11: legrand@marcel.fr | CG11: Autorisation par arrêté préfectoral, à une rupture de traçabilité pour ce déchet | CK11: R4 | CL11: Recyclage | CN11: Lepoint | CO11: Martin | CP11: 87 56 76 87 98 | CQ11: lepoint@outlook.fr
A12: Usine Achenheim | B12: 54850098200044 | C12: 5 rue du Canal 67204 Achenheim | E12: Autres Déchets Industriels | F12: 20 03 01 | H12: {=IFERROR(INDEX(dénomination_ced!$C$2:$C$1102, MATCH(F12, dénomination_ced!$C$1:$C$1102, 0)), "Non classifié")} -> Non classifié | I12: SOLID | J12: WEE2838952 | L12: non concerné | M12: non concerné | N12: non concerné | O12: non concerné | P12: non concerné | R12: 5 rue des fous 65500 Lille | T12: Wienerberger | U12: Baumert | V12: Laura | W12: 06 12 33 76 40 | X12: laura.baumert@wienerberger.com | Z12: Bauvier | AA12: Carinne | AB12: 06 44 44 44 44 | AC12: carinne.bauvier@wienerberger.com | AE12: Fûts 200L | AF12: FUT | AH12: Fût acier 200L | AI12: 200L | AJ12: 2 | AK12: Propriétaire | AO12: non concerné | AP12: non concerné | BG12: Suez | BH12: 50 472 678 700 030 | BI12: 13 route de Rohrshollen 67100 Strasbourg | BJ12: 2167061 | BL12: Camion | BM12: Luc | BN12: 05 44 44 44 44 | BO12: l.c@transpo.fr | BQ12: lechateau | BR12: Laurent | BS12: 09 09 09 09 09 | BT12: lefifi@lemail.fr | CG12: EDIB | CH12: 30 223 694 800 048 | CI12: Route de Krautergersheim 67870 Bischoffsheim | CK12: R12/D1-D10 | CL12: Recyclage + élimination (selon déchets soit incinération soit mise en décharge) | CN12: Lepoint | CO12: Martin | CP12: 87 56 76 87 98 | CQ12: lepoint@outlook.fr
A13: Usine Achenheim | B13: 54850098200044 | C13: 5 rue du Canal 67204 Achenheim | E13: Autres Déchets Industriels | F13: 20 03 01 | H13: {=IFERROR(INDEX(dénomination_ced!$C$2:$C$1102, MATCH(F13, dénomination_ced!$C$1:$C$1102, 0)), "Non classifié")} -> Non classifié | I13: SOLID | J13: WEE2838953 | L13: non concerné | M13: non concerné | N13: non concerné | O13: non concerné | P13: non concerné | R13: 5 rue des fous 65500 Lille | T13: Wienerberger | U13: Baumert | V13: Laura | W13: 06 12 33 76 40 | X13: laura.baumert@wienerberger.com | Z13: Bauvier | AA13: Carinne | AB13: 06 44 44 44 44 | AC13: carinne.bauvier@wienerberger.com | AE13: Fûts 200L | AF13: FUT | AH13: Fût acier 200L | AI13: 200L | AJ13: 2 | AK13: Propriétaire | AO13: non concerné | AP13: non concerné | BG13: Suez | BH13: 50 472 678 700 030 | BI13: 13 route de Rohrshollen 67100 Strasbourg | BJ13: 2167061 | BL13: Camion | BM13: Luc | BN13: 05 44 44 44 44 | BO13: l.c@transpo.fr | BQ13: lechateau | BR13: Laurent | BS13: 09 09 09 09 09 | BT13: lefifi@lemail.fr | CG13: SARDI | CH13: 35 238 105 700 038 | CI13: 15 route du Rohrschollen 67000 Strasbourg | CK13: R1 R5 | CL13: Valorisation énergétique + recyclage | CN13: Lepoint | CO13: Martin | CP13: 87 56 76 87 98 | CQ13: lepoint@outlook.fr
A14: Usine Achenheim | B14: 54850098200044 | C14: 5 rue du Canal 67204 Achenheim | E14: Déchets LIQUIDs et Eaux Usées | F14: 12 03 01* | G14: pièces mécaniques - fontaine dégraissage | H14: {=IFERROR(INDEX(dénomination_ced!$C$2:$C$1102, MATCH(F14, dénomination_ced!$C$1:$C$1102, 0)), "Non classifié")} -> Non classifié | I14: LIQUID | J14: WEE2838954 | L14: non concerné | M14: non concerné | N14: non concerné | O14: non concerné | P14: non concerné | R14: 5 rue des fous 65500 Lille | T14: Wienerberger | U14: Baumert | V14: Laura | W14: 06 12 33 76 40 | X14: laura.baumert@wienerberger.com | Z14: Bauvier | AA14: Carinne | AB14: 06 44 44 44 44 | AC14: carinne.bauvier@wienerberger.com | AE14: Fûts 200L | AF14: FUT | AH14: Fût acier 200L | AI14: 200L | AJ14: 4 | AK14: Propriétaire | AO14: non concerné | AP14: non concerné | BG14: Chimirec Est | BH14: 39933934000016 | BI14: ZI La Haie Sorette 54450 Domjevin | BJ14: TR547592024 | BL14: Camion | BM14: Luc | BN14: 05 44 44 44 44 | BO14: l.c@transpo.fr | BQ14: lechateau | BR14: Laurent | BS14: 09 09 09 09 09 | BT14: lefifi@lemail.fr | BV14: Chimirec Est | BW14: ############# | BX14: ZI La Haie Sorette 54450 Domjevin | BZ14: D13 | CB14: Legrand | CC14: Marcel | CD14: 33 33 33 33 33 | CE14: legrand@marcel.fr | CG14: Autorisation par arrêté préfectoral, à une rupture de traçabilité pour ce déchet | CK14: D5 | CL14: Elimination (décharge) | CN14: Lepoint | CO14: Martin | CP14: 87 56 76 87 98 | CQ14: lepoint@outlook.fr
A15: Usine Achenheim | B15: 54850098200044 | C15: 5 rue du Canal 67204 Achenheim | E15: Déchets de Bois et Papier | F15: 15 01 01 | G15: Emballages en papier/carton | H15: {=IFERROR(INDEX(dénomination_ced!$C$2:$C$1102, MATCH(F15, dénomination_ced!$C$1:$C$1102, 0)), "Non classifié")} -> Non classifié | I15: SOLID | J15: WEE2838955 | L15: non concerné | M15: non concerné | N15: non concerné | O15: non concerné | P15: non concerné | R15: 5 rue des fous 65500 Lille | T15: Wienerberger | U15: Baumert | V15: Laura | W15: 06 12 33 76 40 | X15: laura.baumert@wienerberger.com | Z15: Bauvier | AA15: Carinne | AB15: 06 44 44 44 44 | AC15: carinne.bauvier@wienerberger.com | AE15: Fûts 200L | AF15: FUT | AH15: Fût acier 200L | AI15: 200L | AJ15: 4 | AK15: Propriétaire | AO15: non concerné | AP15: non concerné | BG15: Schroll | BH15: 32 519 337 300 017 | BI15: 6 rue de Cherbourg 67100 Strasbourg | BJ15: 2067081 | BL15: Camion | BM15: Luc | BN15: 05 44 44 44 44 | BO15: l.c@transpo.fr | BQ15: lechateau | BR15: Laurent | BS15: 09 09 09 09 09 | BT15: lefifi@lemail.fr | CG15: Schroll | CH15: 32 519 337 300 017 | CI15: 6 rue de Cherbourg 67100 Strasbourg | CK15: R5 | CL15: Recyclage | CN15: Lepoint | CO15: Martin | CP15: 87 56 76 87 98 | CQ15: lepoint@outlook.fr
A16: Usine Achenheim | B16: 54850098200044 | C16: 5 rue du Canal 67204 Achenheim | E16: Déchets Métalliques | F16: 15 01 10* | G16: Emballages vides souillés métalliques (fûts 200L) | H16: {=IFERROR(INDEX(dénomination_ced!$C$2:$C$1102, MATCH(F16, dénomination_ced!$C$1:$C$1102, 0)), "Non classifié")} -> Non classifié | I16: SOLID | J16: WEE2838956 | L16: UN 1734, acide chlorhydrique, 8, II, (E) | M16: 1734 | N16: acide chlorhydrique | O16: 7 | P16: II | R16: 5 rue des fous 65500 Lille | T16: Wienerberger | U16: Baumert | V16: Laura | W16: 06 12 33 76 40 | X16: laura.baumert@wienerberger.com | Z16: Bauvier | AA16: Carinne | AB16: 06 44 44 44 44 | AC16: carinne.bauvier@wienerberger.com | AE16: Fûts 200L | AF16: FUT | AH16: Fût acier 200L | AI16: 200L | AJ16: 2 | AK16: Propriétaire | AO16: non concerné | AP16: non concerné | BG16: Chimirec Est | BH16: 39933934000016 | BI16: ZI La Haie Sorette 54450 Domjevin | BJ16: TR547592024 | BL16: Camion | BM16: Luc | BN16: 05 44 44 44 44 | BO16: l.c@transpo.fr | BQ16: lechateau | BR16: Laurent | BS16: 09 09 09 09 09 | BT16: lefifi@lemail.fr | BV16: Chimirec Est | BW16: ############# | BX16: ZI La Haie Sorette 54450 Domjevin | BZ16: R12 | CB16: Legrand | CC16: Marcel | CD16: 33 33 33 33 33 | CE16: legrand@marcel.fr | CG16: Autorisation par arrêté préfectoral, à une rupture de traçabilité pour ce déchet | CK16: R12 | CL16: Recyclage | CN16: Lepoint | CO16: Martin | CP16: 87 56 76 87 98 | CQ16: lepoint@outlook.fr
A17: Usine Achenheim | B17: 54850098200044 | C17: 5 rue du Canal 67204 Achenheim | E17: Déchets Métalliques | F17: 17 04 07 | H17: {=IFERROR(INDEX(dénomination_ced!$C$2:$C$1102, MATCH(F17, dénomination_ced!$C$1:$C$1102, 0)), "Non classifié")} -> Non classifié | I17: SOLID | J17: WEE2838957 | L17: non concerné | M17: non concerné | N17: non concerné | O17: non concerné | P17: non concerné | T17: Wienerberger | U17: Baumert | V17: Laura | W17: 06 12 33 76 40 | X17: laura.baumert@wienerberger.com | Z17: Bauvier | AA17: Carinne | AB17: 06 44 44 44 44 | AC17: carinne.bauvier@wienerberger.com | AE17: Fûts 200L | AF17: FUT | AH17: Fût acier 200L | AI17: 200L | AJ17: 1 | AK17: Propriétaire | AO17: non concerné | AP17: non concerné | BG17: Eska (Derichebourg) | BH17: 55 850 281 100 182 | BI17: 56 rue de Metz 57130 Jouy-Aux-Arches | BJ17: 2018-57-1098 | BL17: Camion | BM17: Luc | BN17: 05 44 44 44 44 | BO17: l.c@transpo.fr | BQ17: lechateau | BR17: Laurent | BS17: 09 09 09 09 09 | BT17: lefifi@lemail.fr | CG17: Derichebourg | CH17: 55 850 281 100 091 | CI17: 12 rue de la Minoterie 67000 Strasbourg | CK17: R4 | CL17: Recyclage | CN17: Lepoint | CO17: Martin | CP17: 87 56 76 87 98 | CQ17: lepoint@outlook.fr
A18: Usine Achenheim | B18: 54850098200044 | C18: 5 rue du Canal 67204 Achenheim | E18: Déchets Métalliques | F18: 17 04 07 | G18: (baraque chantier) | H18: {=IFERROR(INDEX(dénomination_ced!$C$2:$C$1102, MATCH(F18, dénomination_ced!$C$1:$C$1102, 0)), "Non classifié")} -> Non classifié | I18: SOLID | J18: WEE2838958 | L18: non concerné | M18: non concerné | N18: non concerné | O18: non concerné | P18: non concerné | T18: Wienerberger | U18: Baumert | V18: Laura | W18: 06 12 33 76 40 | X18: laura.baumert@wienerberger.com | Z18: Bauvier | AA18: Carinne | AB18: 06 44 44 44 44 | AC18: carinne.bauvier@wienerberger.com | AE18: Fûts 200L | AF18: FUT | AH18: Fût acier 200L | AI18: 200L | AJ18: 2 | AK18: Propriétaire | AO18: non concerné | AP18: non concerné | BG18: Transports Steinmetz | BH18: 32 561 507 800 020 | BI18: 12 rue de l'Artisanat 67 Niedermodern | BJ18: 1967071 | BL18: Camion | BM18: Luc | BN18: 05 44 44 44 44 | BO18: l.c@transpo.fr | BQ18: lechateau | BR18: Laurent | BS18: 09 09 09 09 09 | BT18: lefifi@lemail.fr | CG18: Eska Derichebourg | CH18: 55 850 281 100 091 | CI18: 4 route du Rohrschollen 67000 Strasbourg | CK18: R4 | CL18: Recyclage | CN18: Lepoint | CO18: Martin | CP18: 87 56 76 87 98 | CQ18: lepoint@outlook.fr
A19: Usine Achenheim | B19: 54850098200044 | C19: 5 rue du Canal 67204 Achenheim | E19: Autres Déchets Industriels | F19: 17 06 03* | H19: {=IFERROR(INDEX(dénomination_ced!$C$2:$C$1102, MATCH(F19, dénomination_ced!$C$1:$C$1102, 0)), "Non classifié")} -> Non classifié | I19: SOLID | J19: WEE2838959 | L19: UN 1776, acide chlorhydrique, 8, II, (E) | M19: 1776 | N19: acide chlorhydrique | O19: 7 | P19: II | T19: Wienerberger | U19: Baumert | V19: Laura | W19: 06 12 33 76 40 | X19: laura.baumert@wienerberger.com | Z19: Bauvier | AA19: Carinne | AB19: 06 44 44 44 44 | AC19: carinne.bauvier@wienerberger.com | AE19: Fûts 200L | AF19: FUT | AH19: Fût acier 200L | AI19: 200L | AJ19: 4 | AK19: Propriétaire | AO19: non concerné | AP19: non concerné | BG19: Kimmel Transports | BH19: 34782395700043 | BI19: 5 rue de la Logistique 67320 Thal-Drulingen | BJ19: 2022-57-1396 | BL19: Camion | BM19: Luc | BN19: 05 44 44 44 44 | BO19: l.c@transpo.fr | BQ19: lechateau | BR19: Laurent | BS19: 09 09 09 09 09 | BT19: lefifi@lemail.fr | CG19: Suez RR Iws Minerals France | CH19: 43331348300177 | CI19: 14 route de Moivrons 54114 Jeandelaincourt | CK19: D5 | CL19: Elimination (décharge) | CN19: Lepoint | CO19: Martin | CP19: 87 56 76 87 98 | CQ19: lepoint@outlook.fr
A20: Usine Achenheim | B20: 54850098200044 | C20: 5 rue du Canal 67204 Achenheim | E20: Autres Déchets Industriels | F20: 17 06 03* | H20: {=IFERROR(INDEX(dénomination_ced!$C$2:$C$1102, MATCH(F20, dénomination_ced!$C$1:$C$1102, 0)), "Non classifié")} -> Non classifié | I20: SOLID | J20: WEE2838960 | L20: UN 1776, acide chlorhydrique, 8, II, (E) | M20: 1776 | N20: acide chlorhydrique | O20: 7 | P20: II | T20: Wienerberger | U20: Baumert | V20: Laura | W20: 06 12 33 76 40 | X20: laura.baumert@wienerberger.com | Z20: Bauvier | AA20: Carinne | AB20: 06 44 44 44 44 | AC20: carinne.bauvier@wienerberger.com | AE20: Fûts 200L | AF20: FUT | AH20: Fût acier 200L | AI20: 200L | AJ20: 2 | AK20: Propriétaire | AO20: non concerné | AP20: non concerné | BG20: Chimirec Est | BH20: 39933934000016 | BI20: ZI La Haie Sorette 54450 Domjevin | BJ20: TR547592024 | BL20: Camion | BM20: Luc | BN20: 05 44 44 44 44 | BO20: l.c@transpo.fr | BQ20: lechateau | BR20: Laurent | BS20: 09 09 09 09 09 | BT20: lefifi@lemail.fr | BV20: Chimirec Est | BW20: ############# | BX20: ZI La Haie Sorette 54450 Domjevin | BZ20: D5 | CB20: Legrand | CC20: Marcel | CD20: 33 33 33 33 33 | CE20: legrand@marcel.fr | CG20: Autorisation par arrêté préfectoral, à une rupture de traçabilité pour ce déchet | CK20: D5 | CL20: Elimination (décharge) | CN20: Lepoint | CO20: Martin | CP20: 87 56 76 87 98 | CQ20: lepoint@outlook.fr
A21: Usine Achenheim | B21: 54850098200044 | C21: 5 rue du Canal 67204 Achenheim | E21: Emballages Souillés | F21: 15 01 02 | H21: {=IFERROR(INDEX(dénomination_ced!$C$2:$C$1102, MATCH(F21, dénomination_ced!$C$1:$C$1102, 0)), "Non classifié")} -> Non classifié | I21: SOLID | J21: WEE2838961 | L21: non concerné | M21: non concerné | N21: non concerné | O21: non concerné | P21: non concerné | T21: Wienerberger | U21: Baumert | V21: Laura | W21: 06 12 33 76 40 | X21: laura.baumert@wienerberger.com | Z21: Bauvier | AA21: Carinne | AB21: 06 44 44 44 44 | AC21: carinne.bauvier@wienerberger.com | AE21: Fûts 200L | AF21: FUT | AH21: Fût acier 200L | AI21: 200L | AJ21: 1 | AK21: Propriétaire | AO21: non concerné | AP21: non concerné | BG21: Schroll | BH21: 32 519 337 300 017 | BI21: 6 rue de Cherbourg 67100 Strasbourg | BJ21: 2067081 | BL21: Camion | BM21: Luc | BN21: 05 44 44 44 44 | BO21: l.c@transpo.fr | BQ21: lechateau | BR21: Laurent | BS21: 09 09 09 09 09 | BT21: lefifi@lemail.fr | CG21: Schroll | CH21: 32 519 337 300 017 | CI21: 6 rue de Cherbourg 67100 Strasbourg | CK21: R5 | CL21: Recyclage | CN21: Lepoint | CO21: Martin | CP21: 87 56 76 87 98 | CQ21: lepoint@outlook.fr
A22: Usine Achenheim | B22: 54850098200044 | C22: 5 rue du Canal 67204 Achenheim | E22: Huiles et Lubrifiants Usagés | F22: 13 02 08* | H22: {=IFERROR(INDEX(dénomination_ced!$C$2:$C$1102, MATCH(F22, dénomination_ced!$C$1:$C$1102, 0)), "Non classifié")} -> Non classifié | I22: LIQUID | J22: WEE2838962 | L22: UN 1326, acide chlorhydrique, 8, II, (E) | M22: 1326 | N22: acide chlorhydrique | O22: 7 | P22: II | T22: Wienerberger | U22: Baumert | V22: Laura | W22: 06 12 33 76 40 | X22: laura.baumert@wienerberger.com | Z22: Bauvier | AA22: Carinne | AB22: 06 44 44 44 44 | AC22: carinne.bauvier@wienerberger.com | AE22: GRV | AF22: GRV | AH22: Grand Récipient Pour Vrac | AI22: 1000L | AJ22: 1 | AK22: Propriétaire | AO22: non concerné | AP22: non concerné | BG22: Chimirec Est | BH22: 39933934000016 | BI22: ZI La Haie Sorette 54450 Domjevin | BJ22: TR545642019 | BL22: Camion | BM22: Luc | BN22: 05 44 44 44 44 | BO22: l.c@transpo.fr | BQ22: lechateau | BR22: Laurent | BS22: 09 09 09 09 09 | BT22: lefifi@lemail.fr | BV22: Chimirec Est | BW22: ############# | BX22: ZI La Haie Sorette 54450 Domjevin | BZ22: R12 | CB22: Legrand | CC22: Marcel | CD22: 33 33 33 33 33 | CE22: legrand@marcel.fr | CG22: Autorisation par arrêté préfectoral, à une rupture de traçabilité pour ce déchet | CH22: DE814574464 | CK22: R1 | CL22: Valorisation | CN22: Lepoint | CO22: Martin | CP22: 87 56 76 87 98 | CQ22: lepoint@outlook.fr
A23: Usine Achenheim | B23: 54850098200044 | C23: 5 rue du Canal 67204 Achenheim | E23: Autres Déchets Industriels | F23: 15 02 02* | H23: {=IFERROR(INDEX(dénomination_ced!$C$2:$C$1102, MATCH(F23, dénomination_ced!$C$1:$C$1102, 0)), "Non classifié")} -> Non classifié | I23: SOLID | J23: WEE2838963 | L23: UN 1776, acide chlorhydrique, 8, II, (E) | M23: 1776 | N23: acide chlorhydrique | O23: 7 | P23: II | T23: Wienerberger | U23: Baumert | V23: Laura | W23: 06 12 33 76 40 | X23: laura.baumert@wienerberger.com | Z23: Bauvier | AA23: Carinne | AB23: 06 44 44 44 44 | AC23: carinne.bauvier@wienerberger.com | AE23: GRV | AF23: GRV | AH23: Grand Récipient Pour Vrac | AI23: 1000L | AJ23: 1 | AK23: Propriétaire | AO23: non concerné | AP23: non concerné | BG23: Chimirec Est | BH23: 39933934000016 | BI23: ZI La Haie Sorette 54450 Domjevin | BJ23: TR547592024 | BL23: Camion | BM23: Luc | BN23: 05 44 44 44 44 | BO23: l.c@transpo.fr | BQ23: lechateau | BR23: Laurent | BS23: 09 09 09 09 09 | BT23: lefifi@lemail.fr | BV23: Chimirec Est | BW23: ############# | BX23: ZI La Haie Sorette 54450 Domjevin | BZ23: R12 | CB23: Legrand | CC23: Marcel | CD23: 33 33 33 33 33 | CE23: legrand@marcel.fr | CG23: Autorisation par arrêté préfectoral, à une rupture de traçabilité pour ce déchet | CK23: R1 | CL23: Valorisation | CN23: Lepoint | CO23: Martin | CP23: 87 56 76 87 98 | CQ23: lepoint@outlook.fr
A24: Usine Achenheim | B24: 54850098200044 | C24: 5 rue du Canal 67204 Achenheim | E24: Autres Déchets Industriels | F24: 08 01 11* | G24: Matières apparentées aux peintures | H24: {=IFERROR(INDEX(dénomination_ced!$C$2:$C$1102, MATCH(F24, dénomination_ced!$C$1:$C$1102, 0)), "Non classifié")} -> Non classifié | I24: LIQUID | J24: WEE2838964 | L24: UN 1776, acide chlorhydrique, 8, II, (E) | M24: 1776 | N24: acide chlorhydrique | O24: 7 | P24: II | T24: Wienerberger | U24: Baumert | V24: Laura | W24: 06 12 33 76 40 | X24: laura.baumert@wienerberger.com | Z24: Bauvier | AA24: Carinne | AB24: 06 44 44 44 44 | AC24: carinne.bauvier@wienerberger.com | AE24: Benne 5m3 | AF24: BENNE | AH24: Benne ouverte haute acier 5m3 | AI24: 5m3 | AJ24: 1 | AK24: Propriétaire | AO24: non concerné | AP24: non concerné | BG24: Chimirec Est | BH24: 39933934000016 | BI24: ZI La Haie Sorette 54450 Domjevin | BJ24: TR547592024 | BL24: Camion | BM24: Luc | BN24: 05 44 44 44 44 | BO24: l.c@transpo.fr | BQ24: lechateau | BR24: Laurent | BS24: 09 09 09 09 09 | BT24: lefifi@lemail.fr | BV24: Chimirec Est | BW24: ############# | BX24: ZI La Haie Sorette 54450 Domjevin | BZ24: R12 | CB24: Legrand | CC24: Marcel | CD24: 33 33 33 33 33 | CE24: legrand@marcel.fr | CG24: Autorisation par arrêté préfectoral, à une rupture de traçabilité pour ce déchet | CK24: R12 | CL24: Recyclage | CN24: Lepoint | CO24: Martin | CP24: 87 56 76 87 98 | CQ24: lepoint@outlook.fr
A25: Usine Achenheim | B25: 54850098200044 | C25: 5 rue du Canal 67204 Achenheim | E25: Déchets Technologiques et Électroniques | F25: 16 06 03* | H25: {=IFERROR(INDEX(dénomination_ced!$C$2:$C$1102, MATCH(F25, dénomination_ced!$C$1:$C$1102, 0)), "Non classifié")} -> Non classifié | I25: SOLID | J25: WEE2838965 | L25: UN 1776, acide chlorhydrique, 8, II, (E) | M25: 1776 | N25: acide chlorhydrique | O25: 7 | P25: II | T25: Wienerberger | U25: Baumert | V25: Laura | W25: 06 12 33 76 40 | X25: laura.baumert@wienerberger.com | Z25: Bauvier | AA25: Carinne | AB25: 06 44 44 44 44 | AC25: carinne.bauvier@wienerberger.com | AE25: Benne 5m3 | AF25: BENNE | AH25: Benne ouverte haute acier 5m3 | AI25: 5m3 | AJ25: 1 | AK25: Location | AL25: Veolia | AM25: 4534434536433453 | AO25: non concerné | AP25: non concerné | BG25: Chimirec Est | BH25: 39933934000016 | BI25: ZI La Haie Sorette 54450 Domjevin | BJ25: TR547592024 | BL25: Camion | BM25: Luc | BN25: 05 44 44 44 44 | BO25: l.c@transpo.fr | BQ25: lechateau | BR25: Laurent | BS25: 09 09 09 09 09 | BT25: lefifi@lemail.fr | BV25: Chimirec Est | BW25: ############# | BX25: ZI La Haie Sorette 54450 Domjevin | BZ25: R12 | CB25: Legrand | CC25: Marcel | CD25: 33 33 33 33 33 | CE25: legrand@marcel.fr | CG25: Autorisation par arrêté préfectoral, à une rupture de traçabilité pour ce déchet | CK25: R4 | CL25: Recyclage | CN25: Lepoint | CO25: Martin | CP25: 87 56 76 87 98 | CQ25: lepoint@outlook.fr
A26: Usine Achenheim | B26: 54850098200044 | C26: 5 rue du Canal 67204 Achenheim | E26: Non classifié | F26: 17 04 05 | H26: {=IFERROR(INDEX(dénomination_ced!$C$2:$C$1102, MATCH(F26, dénomination_ced!$C$1:$C$1102, 0)), "Non classifié")} -> Non classifié | I26: SOLID | J26: WEE2838966 | L26: non concerné | M26: non concerné | N26: non concerné | O26: non concerné | P26: non concerné | T26: Wienerberger | U26: Baumert | V26: Laura | W26: 06 12 33 76 40 | X26: laura.baumert@wienerberger.com | Z26: Bauvier | AA26: Carinne | AB26: 06 44 44 44 44 | AC26: carinne.bauvier@wienerberger.com | AE26: Benne 5m3 | AF26: BENNE | AH26: Benne ouverte haute acier 5m3 | AI26: 5m3 | AJ26: 1 | AK26: Location | AL26: Veolia | AM26: 4534434536433453 | AO26: non concerné | AP26: non concerné | BG26: Eska (Derichebourg) | BH26: 55 850 281 100 182 | BI26: 56 rue de Metz 57130 Jouy-Aux-Arches | BJ26: 2018-57-1098 | BL26: Camion | BM26: Luc | BN26: 05 44 44 44 44 | BO26: l.c@transpo.fr | BQ26: lechateau | BR26: Laurent | BS26: 09 09 09 09 09 | BT26: lefifi@lemail.fr | CG26: Derichebourg | CH26: 55 850 281 100 091 | CI26: 12 rue de la Minoterie 67000 Strasbourg | CK26: R4 | CL26: Recyclage | CN26: Lepoint | CO26: Martin | CP26: 87 56 76 87 98 | CQ26: lepoint@outlook.fr
A27: Usine Achenheim | B27: 54850098200044 | C27: 5 rue du Canal 67204 Achenheim | E27: Déchets Bâtiment et Construction | F27: 39733 | G27: (après cuisson) | H27: {=IFERROR(INDEX(dénomination_ced!$C$2:$C$1102, MATCH(F27, dénomination_ced!$C$1:$C$1102, 0)), "Non classifié")} -> Non classifié | I27: SOLID | J27: WEE2838967 | L27: non concerné | M27: non concerné | N27: non concerné | O27: non concerné | P27: non concerné | T27: Wienerberger | U27: Baumert | V27: Laura | W27: 06 12 33 76 40 | X27: laura.baumert@wienerberger.com | Z27: Bauvier | AA27: Carinne | AB27: 06 44 44 44 44 | AC27: carinne.bauvier@wienerberger.com | AE27: Benne 5m3 | AF27: BENNE | AH27: Benne ouverte haute acier 5m3 | AI27: 5m3 | AJ27: 1 | AK27: Location | AL27: Veolia | AM27: 4534434536433453 | AO27: non concerné | AP27: non concerné | BG27: Corthum Nordschwarzwald GmbH | BH27: DE292008034 (n° TVA intracommunautaire) | BI27: Im Schwarzenbusch 8 D-76359 Marxzell - Pfaffenrot | BL27: Camion | BM27: Luc | BN27: 05 44 44 44 44 | BO27: l.c@transpo.fr | BQ27: lechateau | BR27: Laurent | BS27: 09 09 09 09 09 | BT27: lefifi@lemail.fr | BV27: Corthum Nordschwarzwald GmbH | BW27: DE292008034 (n° TVA intracommunautaire) | BX27: Im Schwarzenbusch 8 D-76359 Marxzell - Pfaffenrot | BZ27: R13 | CB27: Legrand | CC27: Marcel | CD27: 33 33 33 33 33 | CE27: legrand@marcel.fr | CG27: Corthum Nordschwarzwald GmbH | CH27: DE292008034 (n° TVA intracommunautaire) | CI27: Im Schwarzenbusch 8 D-76359 Marxzell - Pfaffenrot | CK27: R5 | CL27: Valorisation | CN27: Lepoint | CO27: Martin | CP27: 87 56 76 87 98 | CQ27: lepoint@outlook.fr
A28: Usine Achenheim | B28: 54850098200044 | C28: 5 rue du Canal 67204 Achenheim | E28: Déchets Bâtiment et Construction | F28: 39733 | G28: (après cuisson) | H28: {=IFERROR(INDEX(dénomination_ced!$C$2:$C$1102, MATCH(F28, dénomination_ced!$C$1:$C$1102, 0)), "Non classifié")} -> Non classifié | I28: SOLID | J28: WEE2838968 | L28: non concerné | M28: non concerné | N28: non concerné | O28: non concerné | P28: non concerné | T28: Wienerberger | U28: Baumert | V28: Laura | W28: 06 12 33 76 40 | X28: laura.baumert@wienerberger.com | Z28: Bauvier | AA28: Carinne | AB28: 06 44 44 44 44 | AC28: carinne.bauvier@wienerberger.com | AE28: Benne 5m3 | AF28: BENNE | AH28: Benne ouverte haute acier 5m3 | AI28: 5m3 | AJ28: 1 | AK28: Location | AL28: Veolia | AM28: 4534434536433453 | AO28: non concerné | AP28: non concerné | BG28: Corthum Nordschwarzwald GmbH | BH28: DE292008034 (n° TVA intracommunautaire) | BI28: Im Schwarzenbusch 8 D-76359 Marxzell - Pfaffenrot | BL28: Camion | BM28: Luc | BN28: 05 44 44 44 44 | BO28: l.c@transpo.fr | BQ28: lechateau | BR28: Laurent | BS28: 09 09 09 09 09 | BT28: lefifi@lemail.fr | BV28: Corthum Breisgau GmbH | BW28: DE292008034 (n° TVA intracommunautaire) | BX28: Breisgauallee 24, D-79336 Herbolzheim | BZ28: R13 | CB28: Legrand | CC28: Marcel | CD28: 33 33 33 33 33 | CE28: legrand@marcel.fr | CG28: Corthum Breisgau GmbH | CH28: DE292008034 (n° TVA intracommunautaire) | CI28: Breisgauallee 24, D-79336 Herbolzheim | CK28: R5 | CL28: Valorisation | CN28: Lepoint | CO28: Martin | CP28: 87 56 76 87 98 | CQ28: lepoint@outlook.fr
A29: Usine Achenheim | B29: 54850098200044 | C29: 5 rue du Canal 67204 Achenheim | E29: Non classifié | F29: 16 05 07* | G29: (DDQD spéciaux) | H29: {=IFERROR(INDEX(dénomination_ced!$C$2:$C$1102, MATCH(F29, dénomination_ced!$C$1:$C$1102, 0)), "Non classifié")} -> Non classifié | I29: SOLID | J29: WEE2838969 | L29: UN 1776, acide chlorhydrique, 8, II, (E) | M29: 1776 | N29: acide chlorhydrique | O29: 7 | P29: II | T29: Wienerberger | U29: Baumert | V29: Laura | W29: 06 12 33 76 40 | X29: laura.baumert@wienerberger.com | Z29: Bauvier | AA29: Carinne | AB29: 06 44 44 44 44 | AC29: carinne.bauvier@wienerberger.com | AE29: Benne 5m3 | AF29: BENNE | AH29: Benne ouverte haute acier 5m3 | AI29: 5m3 | AJ29: 1 | AK29: Location | AL29: Veolia | AM29: 4534434536433453 | AO29: non concerné | AP29: non concerné | BG29: Chimirec Est | BH29: 39933934000016 | BI29: ZI La Haie Sorette 54450 Domjevin | BJ29: TR547592024 | BL29: Camion | BM29: Luc | BN29: 05 44 44 44 44 | BO29: l.c@transpo.fr | BQ29: lechateau | BR29: Laurent | BS29: 09 09 09 09 09 | BT29: lefifi@lemail.fr | BV29: Chimirec Est | BW29: ############# | BX29: ZI La Haie Sorette 54450 Domjevin | BZ29: D13 | CB29: Legrand | CC29: Marcel | CD29: 33 33 33 33 33 | CE29: legrand@marcel.fr | CG29: Autorisation par arrêté préfectoral, à une rupture de traçabilité pour ce déchet | CK29: D9 | CL29: Elimination | CN29: Lepoint | CO29: Martin | CP29: 87 56 76 87 98 | CQ29: lepoint@outlook.fr
A30: Usine Achenheim | B30: 54850098200044 | C30: 5 rue du Canal 67204 Achenheim | E30: Autres Déchets Industriels | F30: 37176 | G30: (avant cuisson) | H30: {=IFERROR(INDEX(dénomination_ced!$C$2:$C$1102, MATCH(F30, dénomination_ced!$C$1:$C$1102, 0)), "Non classifié")} -> Non classifié | I30: SOLID | J30: WEE2838970 | L30: non concerné | M30: non concerné | N30: non concerné | O30: non concerné | P30: non concerné | T30: Wienerberger | U30: Baumert | V30: Laura | W30: 06 12 33 76 40 | X30: laura.baumert@wienerberger.com | Z30: Bauvier | AA30: Carinne | AB30: 06 44 44 44 44 | AC30: carinne.bauvier@wienerberger.com | AE30: Benne 5m3 | AF30: BENNE | AH30: Benne ouverte haute acier 5m3 | AI30: 5m3 | AJ30: 1 | AK30: Location | AL30: Veolia | AM30: 4534434536433453 | AO30: non concerné | AP30: non concerné | BG30: SAS Eta Sattler Materne et Fils | BH30: 42196220000018 | BI30: 82 rue du Moulin 67520 Kirchheim | BL30: Camion | BM30: Luc | BN30: 05 44 44 44 44 | BO30: l.c@transpo.fr | BQ30: lechateau | BR30: Laurent | BS30: 09 09 09 09 09 | BT30: lefifi@lemail.fr | BV30: Carrière Wienerberger | BX30: Lieu-dit « Bossenroth » 67204 Achenheim | CB30: Legrand | CC30: Marcel | CD30: 33 33 33 33 33 | CE30: legrand@marcel.fr | CG30: Carrière Wienerberger | CI30: Lieu-dit « Bossenroth » 67204 Achenheim | CN30: Lepoint | CO30: Martin | CP30: 87 56 76 87 98 | CQ30: lepoint@outlook.fr
A31: Usine Achenheim | B31: 54850098200044 | C31: 5 rue du Canal 67204 Achenheim | E31: Déchets Bâtiment et Construction | F31: 19 10 04 | G31: Résidus de broyage et poussières | H31: {=IFERROR(INDEX(dénomination_ced!$C$2:$C$1102, MATCH(F31, dénomination_ced!$C$1:$C$1102, 0)), "Non classifié")} -> Non classifié | I31: SOLID | J31: WEE2838971 | L31: non concerné | M31: non concerné | N31: non concerné | O31: non concerné | P31: non concerné | T31: Wienerberger | U31: Baumert | V31: Laura | W31: 06 12 33 76 40 | X31: laura.baumert@wienerberger.com | Z31: Bauvier | AA31: Carinne | AB31: 06 44 44 44 44 | AC31: carinne.bauvier@wienerberger.com | AE31: Benne 15m3 | AF31: BENNE | AH31: Benne double acier 15m3 | AI31: 15m3 | AJ31: 1 | AK31: Location | AL31: Veolia | AM31: 4534434536433453 | AO31: non concerné | AP31: non concerné | BG31: Eska (Derichebourg) | BH31: 55 850 281 100 182 | BI31: 56 rue de Metz 57130 Jouy-Aux-Arches | BJ31: 2018-57-1098 | BL31: Camion | BM31: Luc | BN31: 05 44 44 44 44 | BO31: l.c@transpo.fr | BQ31: lechateau | BR31: Laurent | BS31: 09 09 09 09 09 | BT31: lefifi@lemail.fr | CG31: Derichebourg | CH31: 55 850 281 100 091 | CI31: 12 rue de la Minoterie 67000 Strasbourg | CK31: R1/D1 | CL31: Valorisation énergétique / élimination | CN31: Lepoint | CO31: Martin | CP31: 87 56 76 87 98 | CQ31: lepoint@outlook.fr
A32: Usine Seltz | B32: 54850098200267 | C32: 25 rue de la Gare 67470 Seltz | E32: Aérosols et Gaz | F32: 16 05 04* | H32: {=IFERROR(INDEX(dénomination_ced!$C$2:$C$1102, MATCH(F32, dénomination_ced!$C$1:$C$1102, 0)), "Non classifié")} -> Non classifié | I32: GASEOUS | J32: WEE2838972 | L32: non concerné | M32: non concerné | N32: non concerné | O32: non concerné | P32: non concerné | T32: Wienerberger | U32: Baumert | V32: Laura | W32: 06 12 33 76 40 | X32: laura.baumert@wienerberger.com | Z32: Bauvier | AA32: Carinne | AB32: 06 44 44 44 44 | AC32: carinne.bauvier@wienerberger.com | AE32: Benne 15m3 | AF32: BENNE | AH32: Benne double acier 15m3 | AI32: 15m3 | AJ32: 1 | AK32: Location | AL32: Veolia | AM32: 4534434536433453 | AO32: non concerné | AP32: non concerné | BG32: Chimirec Est | BH32: 39 933 934 000 016 | BI32: ZI La Haie Sorette 54450 Domjevin | BJ32: TR547592024 | BL32: Camion | BM32: Luc | BN32: 05 44 44 44 44 | BO32: l.c@transpo.fr | BQ32: lechateau | BR32: Laurent | BS32: 09 09 09 09 09 | BT32: lefifi@lemail.fr | BV32: Chimirec Est | BW32: ############# | BX32: ZI La Haie Sorette 54450 Domjevin | BZ32: R12 | CB32: Legrand | CC32: Marcel | CD32: 33 33 33 33 33 | CE32: legrand@marcel.fr | CG32: Autorisation par arrêté préfectoral, à une rupture de traçabilité pour ce déchet | CK32: R4 | CL32: Recyclage | CN32: Lepoint | CO32: Martin | CP32: 87 56 76 87 98 | CQ32: lepoint@outlook.fr
A33: Usine Seltz | B33: 54850098200267 | C33: 25 rue de la Gare 67470 Seltz | E33: Déchets Métalliques | F33: 17 04 02 | H33: {=IFERROR(INDEX(dénomination_ced!$C$2:$C$1102, MATCH(F33, dénomination_ced!$C$1:$C$1102, 0)), "Non classifié")} -> Non classifié | I33: SOLID | J33: WEE2838973 | L33: non concerné | M33: non concerné | N33: non concerné | O33: non concerné | P33: non concerné | T33: Wienerberger | U33: Baumert | V33: Laura | W33: 06 12 33 76 40 | X33: laura.baumert@wienerberger.com | Z33: Bauvier | AA33: Carinne | AB33: 06 44 44 44 44 | AC33: carinne.bauvier@wienerberger.com | AE33: Benne 15m3 | AF33: BENNE | AH33: Benne double acier 15m3 | AI33: 15m3 | AJ33: 1 | AK33: Location | AL33: Veolia | AM33: 4534434536433453 | AO33: non concerné | AP33: non concerné | BG33: SAS Transenvironnement | BH33: 50 390 796 600 017 | BI33: La Guerre 14540 Castine En Plaine | BJ33: 2020/24 | BL33: Camion | BM33: Luc | BN33: 05 44 44 44 44 | BO33: l.c@transpo.fr | BQ33: lechateau | BR33: Laurent | BS33: 09 09 09 09 09 | BT33: lefifi@lemail.fr | BV33: ESKA Derichebourg | BW33: ############# | BX33: Rue de Riedseltz Altenstadt 67160 Wissembourg | BZ33: R13 | CB33: Legrand | CC33: Marcel | CD33: 33 33 33 33 33 | CE33: legrand@marcel.fr | CG33: ESKA Derichebourg | CH33: 65 382 053 001 073 | CI33: Rue de Riedseltz Altenstadt 67160 Wissembourg | CK33: R4 | CL33: Recyclage | CN33: Lepoint | CO33: Martin | CP33: 87 56 76 87 98 | CQ33: lepoint@outlook.fr
A34: Usine Seltz | B34: 54850098200267 | C34: 25 rue de la Gare 67470 Seltz | E34: Déchets de Bois et Papier | F34: 15 01 03 | H34: {=IFERROR(INDEX(dénomination_ced!$C$2:$C$1102, MATCH(F34, dénomination_ced!$C$1:$C$1102, 0)), "Non classifié")} -> Non classifié | I34: SOLID | J34: WEE2838974 | L34: non concerné | M34: non concerné | N34: non concerné | O34: non concerné | P34: non concerné | T34: Wienerberger | U34: Baumert | V34: Laura | W34: 06 12 33 76 40 | X34: laura.baumert@wienerberger.com | Z34: Bauvier | AA34: Carinne | AB34: 06 44 44 44 44 | AC34: carinne.bauvier@wienerberger.com | AE34: Benne 15m3 | AF34: BENNE | AH34: Benne double acier 15m3 | AI34: 15m3 | AJ34: 1 | AK34: Location | AL34: Veolia | AM34: 4534434536433453 | AO34: non concerné | AP34: non concerné | BG34: SUEZ RV Nord Est | BH34: 50 472 678 700 030 | BI34: 13 Route de Rohrshollen 67100 Strasbourg | BJ34: 2167061 | BL34: Camion | BM34: Luc | BN34: 05 44 44 44 44 | BO34: l.c@transpo.fr | BQ34: lechateau | BR34: Laurent | BS34: 09 09 09 09 09 | BT34: lefifi@lemail.fr | CG34: Sardi | CH34: 35 238 105 700 038 | CI34: Rue des Frères Lumières 67170 Brumath | CK34: R5 | CL34: Recyclage | CN34: Lepoint | CO34: Martin | CP34: 87 56 76 87 98 | CQ34: lepoint@outlook.fr
A35: Usine Seltz | B35: 54850098200267 | C35: 25 rue de la Gare 67470 Seltz | E35: Déchets de Bois et Papier | F35: 15 01 03 | H35: {=IFERROR(INDEX(dénomination_ced!$C$2:$C$1102, MATCH(F35, dénomination_ced!$C$1:$C$1102, 0)), "Non classifié")} -> Non classifié | I35: SOLID | J35: WEE2838975 | L35: non concerné | M35: non concerné | N35: non concerné | O35: non concerné | P35: non concerné | T35: Wienerberger | U35: Baumert | V35: Laura | W35: 06 12 33 76 40 | X35: laura.baumert@wienerberger.com | Z35: Bauvier | AA35: Carinne | AB35: 06 44 44 44 44 | AC35: carinne.bauvier@wienerberger.com | AE35: Benne 15m3 | AF35: BENNE | AH35: Benne double acier 15m3 | AI35: 15m3 | AJ35: 1 | AK35: Location | AL35: Veolia | AM35: 4534434536433453 | AO35: non concerné | AP35: non concerné | BG35: SUEZ RV Nord Est | BH35: 50 472 678 700 030 | BI35: 13 Route de Rohrshollen 67100 Strasbourg | BJ35: 2167061 | BL35: Camion | BM35: Luc | BN35: 05 44 44 44 44 | BO35: l.c@transpo.fr | BQ35: lechateau | BR35: Laurent | BS35: 09 09 09 09 09 | BT35: lefifi@lemail.fr | BV35: EDIB | BW35: ############# | BX35: Quai du Canal 67270 Hochfelden | BZ35: R12 | CB35: Legrand | CC35: Marcel | CD35: 33 33 33 33 33 | CE35: legrand@marcel.fr | CG35: EDIB | CH35: 30 223 694 800 030 | CI35: Quai du Canal 67270 Hochfelden | CK35: R5 | CL35: Recyclage | CN35: Lepoint | CO35: Martin | CP35: 87 56 76 87 98 | CQ35: lepoint@outlook.fr
A36: Usine Seltz | B36: 54850098200267 | C36: 25 rue de la Gare 67470 Seltz | E36: Déchets Plastiques | F36: 15 01 02 | H36: {=IFERROR(INDEX(dénomination_ced!$C$2:$C$1102, MATCH(F36, dénomination_ced!$C$1:$C$1102, 0)), "Non classifié")} -> Non classifié | I36: SOLID | J36: WEE2838976 | L36: non concerné | M36: non concerné | N36: non concerné | O36: non concerné | P36: non concerné | R36: 5 rue des fous 65500 Lille | T36: Wienerberger | U36: Baumert | V36: Laura | W36: 06 12 33 76 40 | X36: laura.baumert@wienerberger.com | Z36: Bauvier | AA36: Carinne | AB36: 06 44 44 44 44 | AC36: carinne.bauvier@wienerberger.com | AE36: Benne 15m3 | AF36: BENNE | AH36: Benne double acier 15m3 | AI36: 15m3 | AJ36: 1 | AK36: Location | AL36: Veolia | AM36: 4534434536433453 | AO36: non concerné | AP36: non concerné | BG36: Savoir et Compétences emploi/ELISE | BH36: 47 897 787 900 012 | BI36: 5 Rue Denis Papin 67400 ILLKIRCH | BJ36: 1967066 | BL36: Camion | BM36: Luc | BN36: 05 44 44 44 44 | BO36: l.c@transpo.fr | BQ36: lechateau | BR36: Laurent | BS36: 09 09 09 09 09 | BT36: lefifi@lemail.fr | BV36: Savoir et Compétences emploi/ELISE | BW36: ############# | BX36: 5 Rue Denis Papin 67400 ILLKIRCH | BZ36: R13 | CB36: Legrand | CC36: Marcel | CD36: 33 33 33 33 33 | CE36: legrand@marcel.fr | CG36: VEOLIA | CH36: 30 321 551 100 161 | CI36: ZI Sandrgube 67560 ROSHEIM | CK36: R3 | CL36: Recyclage | CN36: Lepoint | CO36: Martin | CP36: 87 56 76 87 98 | CQ36: lepoint@outlook.fr
A37: Usine Seltz | B37: 54850098200267 | C37: 25 rue de la Gare 67470 Seltz | E37: Déchets Métalliques | F37: 17 04 01 | H37: {=IFERROR(INDEX(dénomination_ced!$C$2:$C$1102, MATCH(F37, dénomination_ced!$C$1:$C$1102, 0)), "Non classifié")} -> Non classifié | I37: SOLID | J37: WEE2838977 | L37: non concerné | M37: non concerné | N37: non concerné | O37: non concerné | P37: non concerné | R37: 5 rue des fous 65500 Lille | T37: Wienerberger | U37: Baumert | V37: Laura | W37: 06 12 33 76 40 | X37: laura.baumert@wienerberger.com | Z37: Bauvier | AA37: Carinne | AB37: 06 44 44 44 44 | AC37: carinne.bauvier@wienerberger.com | AE37: Benne 15m3 | AF37: BENNE | AH37: Benne double acier 15m3 | AI37: 15m3 | AJ37: 1 | AK37: Location | AL37: Veolia | AM37: 4534434536433453 | AO37: non concerné | AP37: non concerné | BG37: SAS Transenvironnement | BH37: 50 390 796 600 017 | BI37: La Guerre 14540 Castine En Plaine | BJ37: 2020/24 | BL37: Camion | BM37: Luc | BN37: 05 44 44 44 44 | BO37: l.c@transpo.fr | BQ37: lechateau | BR37: Laurent | BS37: 09 09 09 09 09 | BT37: lefifi@lemail.fr | BV37: ESKA Derichebourg | BW37: ############# | BX37: Rue de Riedseltz Altenstadt 67160 Wissembourg | BZ37: R13 | CB37: Legrand | CC37: Marcel | CD37: 33 33 33 33 33 | CE37: legrand@marcel.fr | CG37: ESKA Derichebourg | CH37: 65 382 053 001 073 | CI37: Rue de Riedseltz Altenstadt 67160 Wissembourg | CK37: R4 | CL37: Recyclage | CN37: Lepoint | CO37: Martin | CP37: 87 56 76 87 98 | CQ37: lepoint@outlook.fr
A38: Usine Seltz | B38: 54850098200267 | C38: 25 rue de la Gare 67470 Seltz | E38: Déchets Métalliques | F38: 15 01 04 | H38: {=IFERROR(INDEX(dénomination_ced!$C$2:$C$1102, MATCH(F38, dénomination_ced!$C$1:$C$1102, 0)), "Non classifié")} -> Non classifié | I38: SOLID | J38: WEE2838978 | L38: non concerné | M38: non concerné | N38: non concerné | O38: non concerné | P38: non concerné | R38: 5 rue des fous 65500 Lille | T38: Wienerberger | U38: Baumert | V38: Laura | W38: 06 12 33 76 40 | X38: laura.baumert@wienerberger.com | Z38: Bauvier | AA38: Carinne | AB38: 06 44 44 44 44 | AC38: carinne.bauvier@wienerberger.com | AE38: Benne 15m3 | AF38: BENNE | AH38: Benne double acier 15m3 | AI38: 15m3 | AJ38: 1 | AK38: Propriétaire | AO38: non concerné | AP38: non concerné | BG38: Savoir et Compétences emploi/ELISE | BH38: 47 897 787 900 012 | BI38: 5 Rue Denis Papin 67400 ILLKIRCH | BJ38: 1967066 | BL38: Camion | BM38: Luc | BN38: 05 44 44 44 44 | BO38: l.c@transpo.fr | BQ38: lechateau | BR38: Laurent | BS38: 09 09 09 09 09 | BT38: lefifi@lemail.fr | BV38: Savoir et Compétences emploi/ELISE | BW38: ############# | BX38: 5 Rue Denis Papin 67400 ILLKIRCH | BZ38: R13 | CB38: Legrand | CC38: Marcel | CD38: 33 33 33 33 33 | CE38: legrand@marcel.fr | CG38: VEOLIA | CH38: 30 321 551 100 161 | CI38: ZI Sandrgube 67560 ROSHEIM | CK38: R4 | CL38: Recyclage | CN38: Lepoint | CO38: Martin | CP38: 87 56 76 87 98 | CQ38: lepoint@outlook.fr
A39: Usine Seltz | B39: 54850098200267 | C39: 25 rue de la Gare 67470 Seltz | E39: Non classifié | F39: 36375 | H39: {=IFERROR(INDEX(dénomination_ced!$C$2:$C$1102, MATCH(F39, dénomination_ced!$C$1:$C$1102, 0)), "Non classifié")} -> Non classifié | I39: SOLID | J39: WEE2838979 | L39: non concerné | M39: non concerné | N39: non concerné | O39: non concerné | P39: non concerné | R39: 5 rue des fous 65500 Lille | T39: Wienerberger | U39: Baumert | V39: Laura | W39: 06 12 33 76 40 | X39: laura.baumert@wienerberger.com | Z39: Bauvier | AA39: Carinne | AB39: 06 44 44 44 44 | AC39: carinne.bauvier@wienerberger.com | AE39: Benne 15m3 | AF39: BENNE | AH39: Benne double acier 15m3 | AI39: 15m3 | AJ39: 1 | AK39: Propriétaire | AO39: non concerné | AP39: non concerné | BG39: Lyreco France | BH39: 57 172 266 900 355 | BI39: 9 rue de Bayonne 67100 Strasbourg | BJ39: 2020/CTD/026 | BL39: Camion | BM39: Luc | BN39: 05 44 44 44 44 | BO39: l.c@transpo.fr | BQ39: lechateau | BR39: Laurent | BS39: 09 09 09 09 09 | BT39: lefifi@lemail.fr | BV39: Lyreco France | BW39: ############# | BX39: Route de la Plaine 71660 Digoin | BZ39: R13 | CB39: Legrand | CC39: Marcel | CD39: 33 33 33 33 33 | CE39: legrand@marcel.fr | CG39: Les ateliers du bocage | CH39: 38 525 318 200 013 | CI39: La Boujalière 79140 Le Pin | CK39: R12/R5 | CL39: Recyclage | CN39: Lepoint | CO39: Martin | CP39: 87 56 76 87 98 | CQ39: lepoint@outlook.fr
